INFO:aiogram.dispatcher.dispatcher:Stop polling...
WARNING:aiogram:Goodbye!
INFO:aiogram:Bot: SF Expense App bot [@SF_Expense_App_bot]
INFO:aiogram.dispatcher.dispatcher:Start polling.
INFO:root:
        Успешный вход пользователя: Klimchik
        Офис: Office 1
        Email: shpektras@gmail.com
INFO:root:
        Успешный выход пользователя: 
        Илья
        Климчик
        None
ERROR:aiogram.dispatcher.dispatcher:Cause exception while getting updates.
Traceback (most recent call last):
  File "C:\Users\klim\AppData\Roaming\Python\Python39\site-packages\aiogram\bot\api.py", line 139, in make_request
    async with session.post(url, data=req, **kwargs) as response:
  File "C:\Users\klim\AppData\Roaming\Python\Python39\site-packages\aiohttp\client.py", line 1117, in __aenter__
    self._resp = await self._coro
  File "C:\Users\klim\AppData\Roaming\Python\Python39\site-packages\aiohttp\client.py", line 544, in _request
    await resp.start(conn)
  File "C:\Users\klim\AppData\Roaming\Python\Python39\site-packages\aiohttp\client_reqrep.py", line 890, in start
    message, payload = await self._protocol.read()  # type: ignore
  File "C:\Users\klim\AppData\Roaming\Python\Python39\site-packages\aiohttp\streams.py", line 604, in read
    await self._waiter
aiohttp.client_exceptions.ClientOSError: [Errno 1] [SSL: APPLICATION_DATA_AFTER_CLOSE_NOTIFY] application data after close notify (_ssl.c:2750)

During handling of the above exception, another exception occurred:

Traceback (most recent call last):
  File "C:\Users\klim\AppData\Roaming\Python\Python39\site-packages\aiogram\dispatcher\dispatcher.py", line 380, in start_polling
    updates = await self.bot.get_updates(limit=limit, offset=offset, timeout=timeout)
  File "C:\Users\klim\AppData\Roaming\Python\Python39\site-packages\aiogram\bot\bot.py", line 97, in get_updates
    result = await self.request(api.Methods.GET_UPDATES, payload)
  File "C:\Users\klim\AppData\Roaming\Python\Python39\site-packages\aiogram\bot\base.py", line 208, in request
    return await api.make_request(self.session, self.server, self.__token, method, data, files,
  File "C:\Users\klim\AppData\Roaming\Python\Python39\site-packages\aiogram\bot\api.py", line 142, in make_request
    raise exceptions.NetworkError(f"aiohttp client throws an error: {e.__class__.__name__}: {e}")
aiogram.utils.exceptions.NetworkError: Aiohttp client throws an error: ClientOSError: [Errno 1] [SSL: APPLICATION_DATA_AFTER_CLOSE_NOTIFY] application data after close notify (_ssl.c:2750)
ERROR:asyncio:Task exception was never retrieved
future: <Task finished name='Task-35' coro=<Dispatcher._process_polling_updates() done, defined at C:\Users\klim\AppData\Roaming\Python\Python39\site-packages\aiogram\dispatcher\dispatcher.py:401> exception=MessageToDeleteNotFound('Message to delete not found')>
Traceback (most recent call last):
  File "C:\Users\klim\Documents\vs code salesfoce\sfExpenceAppBot\secondbot.py", line 272, in echo_message
    valid = validate_email(emailvar)
  File "C:\Users\klim\AppData\Roaming\Python\Python39\site-packages\email_validator\__init__.py", line 208, in validate_email
    raise EmailSyntaxError("The email address is not valid. It must have exactly one @-sign.")
email_validator.EmailSyntaxError: The email address is not valid. It must have exactly one @-sign.

During handling of the above exception, another exception occurred:

Traceback (most recent call last):
  File "C:\Users\klim\AppData\Roaming\Python\Python39\site-packages\aiogram\dispatcher\dispatcher.py", line 409, in _process_polling_updates
    for responses in itertools.chain.from_iterable(await self.process_updates(updates, fast)):
  File "C:\Users\klim\AppData\Roaming\Python\Python39\site-packages\aiogram\dispatcher\dispatcher.py", line 238, in process_updates
    return await asyncio.gather(*tasks)
  File "C:\Users\klim\AppData\Roaming\Python\Python39\site-packages\aiogram\dispatcher\handler.py", line 116, in notify
    response = await handler_obj.handler(*args, **partial_data)
  File "C:\Users\klim\AppData\Roaming\Python\Python39\site-packages\aiogram\dispatcher\dispatcher.py", line 259, in process_update
    return await self.message_handlers.notify(update.message)
  File "C:\Users\klim\AppData\Roaming\Python\Python39\site-packages\aiogram\dispatcher\handler.py", line 116, in notify
    response = await handler_obj.handler(*args, **partial_data)
  File "C:\Users\klim\Documents\vs code salesfoce\sfExpenceAppBot\secondbot.py", line 293, in echo_message
    await bot.delete_message(msg.chat.id, getBotLatestMessageId())
  File "C:\Users\klim\AppData\Roaming\Python\Python39\site-packages\aiogram\bot\bot.py", line 2485, in delete_message
    return await self.request(api.Methods.DELETE_MESSAGE, payload)
  File "C:\Users\klim\AppData\Roaming\Python\Python39\site-packages\aiogram\bot\base.py", line 208, in request
    return await api.make_request(self.session, self.server, self.__token, method, data, files,
  File "C:\Users\klim\AppData\Roaming\Python\Python39\site-packages\aiogram\bot\api.py", line 140, in make_request
    return check_result(method, response.content_type, response.status, await response.text())
  File "C:\Users\klim\AppData\Roaming\Python\Python39\site-packages\aiogram\bot\api.py", line 115, in check_result
    exceptions.BadRequest.detect(description)
  File "C:\Users\klim\AppData\Roaming\Python\Python39\site-packages\aiogram\utils\exceptions.py", line 140, in detect
    raise err(cls.text or description)
aiogram.utils.exceptions.MessageToDeleteNotFound: Message to delete not found
INFO:root:
        Успешный вход пользователя: Klimchik
        Офис: Office 1
        Email: shpektras@gmail.com
INFO:root:
        Успешный выход пользователя: 
        Илья
        Климчик
        None
ERROR:aiogram.dispatcher.dispatcher:Cause exception while getting updates.
Traceback (most recent call last):
  File "C:\Users\klim\AppData\Roaming\Python\Python39\site-packages\aiogram\bot\api.py", line 139, in make_request
    async with session.post(url, data=req, **kwargs) as response:
  File "C:\Users\klim\AppData\Roaming\Python\Python39\site-packages\aiohttp\client.py", line 1117, in __aenter__
    self._resp = await self._coro
  File "C:\Users\klim\AppData\Roaming\Python\Python39\site-packages\aiohttp\client.py", line 544, in _request
    await resp.start(conn)
  File "C:\Users\klim\AppData\Roaming\Python\Python39\site-packages\aiohttp\client_reqrep.py", line 890, in start
    message, payload = await self._protocol.read()  # type: ignore
  File "C:\Users\klim\AppData\Roaming\Python\Python39\site-packages\aiohttp\streams.py", line 604, in read
    await self._waiter
aiohttp.client_exceptions.ClientOSError: [Errno 1] [SSL: APPLICATION_DATA_AFTER_CLOSE_NOTIFY] application data after close notify (_ssl.c:2750)

During handling of the above exception, another exception occurred:

Traceback (most recent call last):
  File "C:\Users\klim\AppData\Roaming\Python\Python39\site-packages\aiogram\dispatcher\dispatcher.py", line 380, in start_polling
    updates = await self.bot.get_updates(limit=limit, offset=offset, timeout=timeout)
  File "C:\Users\klim\AppData\Roaming\Python\Python39\site-packages\aiogram\bot\bot.py", line 97, in get_updates
    result = await self.request(api.Methods.GET_UPDATES, payload)
  File "C:\Users\klim\AppData\Roaming\Python\Python39\site-packages\aiogram\bot\base.py", line 208, in request
    return await api.make_request(self.session, self.server, self.__token, method, data, files,
  File "C:\Users\klim\AppData\Roaming\Python\Python39\site-packages\aiogram\bot\api.py", line 142, in make_request
    raise exceptions.NetworkError(f"aiohttp client throws an error: {e.__class__.__name__}: {e}")
aiogram.utils.exceptions.NetworkError: Aiohttp client throws an error: ClientOSError: [Errno 1] [SSL: APPLICATION_DATA_AFTER_CLOSE_NOTIFY] application data after close notify (_ssl.c:2750)
INFO:aiogram.dispatcher.dispatcher:Stop polling...
WARNING:aiogram:Goodbye!
INFO:aiogram:Bot: SF Expense App bot [@SF_Expense_App_bot]
INFO:aiogram.dispatcher.dispatcher:Start polling.
INFO:root:
        Успешный вход пользователя: Klimchik
        Офис: Office 1
        Email: shpektras@gmail.com
INFO:root:
        Успешный выход пользователя: 
        :)
        None
        Klik2019
INFO:root:
        Успешный вход пользователя: Klimchik
        Офис: Office 1
        Email: shpektras@gmail.com
INFO:root:
        Успешный выход пользователя: 
        Илья
        Климчик
        None
INFO:root:
        Успешный вход пользователя: Klimchik
        Офис: Office 1
        Email: shpektras@gmail.com
INFO:root:
        Успешный выход пользователя: 
        Илья
        Климчик
        None
INFO:root:
        Успешный вход пользователя: Klimchik
        Офис: Office 1
        Email: shpektras@gmail.com
ERROR:asyncio:Task exception was never retrieved
future: <Task finished name='Task-118' coro=<Dispatcher._process_polling_updates() done, defined at C:\Users\klim\AppData\Roaming\Python\Python39\site-packages\aiogram\dispatcher\dispatcher.py:401> exception=MessageToDeleteNotFound('Message to delete not found')>
Traceback (most recent call last):
  File "C:\Users\klim\AppData\Roaming\Python\Python39\site-packages\aiogram\dispatcher\dispatcher.py", line 409, in _process_polling_updates
    for responses in itertools.chain.from_iterable(await self.process_updates(updates, fast)):
  File "C:\Users\klim\AppData\Roaming\Python\Python39\site-packages\aiogram\dispatcher\dispatcher.py", line 238, in process_updates
    return await asyncio.gather(*tasks)
  File "C:\Users\klim\AppData\Roaming\Python\Python39\site-packages\aiogram\dispatcher\handler.py", line 116, in notify
    response = await handler_obj.handler(*args, **partial_data)
  File "C:\Users\klim\AppData\Roaming\Python\Python39\site-packages\aiogram\dispatcher\dispatcher.py", line 259, in process_update
    return await self.message_handlers.notify(update.message)
  File "C:\Users\klim\AppData\Roaming\Python\Python39\site-packages\aiogram\dispatcher\handler.py", line 116, in notify
    response = await handler_obj.handler(*args, **partial_data)
  File "C:\Users\klim\Documents\vs code salesfoce\sfExpenceAppBot\secondbot.py", line 337, in echo_message
    await bot.delete_message(msg.chat.id, getBotLatestMessageId())
  File "C:\Users\klim\AppData\Roaming\Python\Python39\site-packages\aiogram\bot\bot.py", line 2485, in delete_message
    return await self.request(api.Methods.DELETE_MESSAGE, payload)
  File "C:\Users\klim\AppData\Roaming\Python\Python39\site-packages\aiogram\bot\base.py", line 208, in request
    return await api.make_request(self.session, self.server, self.__token, method, data, files,
  File "C:\Users\klim\AppData\Roaming\Python\Python39\site-packages\aiogram\bot\api.py", line 140, in make_request
    return check_result(method, response.content_type, response.status, await response.text())
  File "C:\Users\klim\AppData\Roaming\Python\Python39\site-packages\aiogram\bot\api.py", line 115, in check_result
    exceptions.BadRequest.detect(description)
  File "C:\Users\klim\AppData\Roaming\Python\Python39\site-packages\aiogram\utils\exceptions.py", line 140, in detect
    raise err(cls.text or description)
aiogram.utils.exceptions.MessageToDeleteNotFound: Message to delete not found
ERROR:asyncio:Task exception was never retrieved
future: <Task finished name='Task-124' coro=<Dispatcher._process_polling_updates() done, defined at C:\Users\klim\AppData\Roaming\Python\Python39\site-packages\aiogram\dispatcher\dispatcher.py:401> exception=MessageToDeleteNotFound('Message to delete not found')>
Traceback (most recent call last):
  File "C:\Users\klim\AppData\Roaming\Python\Python39\site-packages\aiogram\dispatcher\dispatcher.py", line 409, in _process_polling_updates
    for responses in itertools.chain.from_iterable(await self.process_updates(updates, fast)):
  File "C:\Users\klim\AppData\Roaming\Python\Python39\site-packages\aiogram\dispatcher\dispatcher.py", line 238, in process_updates
    return await asyncio.gather(*tasks)
  File "C:\Users\klim\AppData\Roaming\Python\Python39\site-packages\aiogram\dispatcher\handler.py", line 116, in notify
    response = await handler_obj.handler(*args, **partial_data)
  File "C:\Users\klim\AppData\Roaming\Python\Python39\site-packages\aiogram\dispatcher\dispatcher.py", line 259, in process_update
    return await self.message_handlers.notify(update.message)
  File "C:\Users\klim\AppData\Roaming\Python\Python39\site-packages\aiogram\dispatcher\handler.py", line 116, in notify
    response = await handler_obj.handler(*args, **partial_data)
  File "C:\Users\klim\Documents\vs code salesfoce\sfExpenceAppBot\secondbot.py", line 337, in echo_message
    await bot.delete_message(msg.chat.id, getBotLatestMessageId())
  File "C:\Users\klim\AppData\Roaming\Python\Python39\site-packages\aiogram\bot\bot.py", line 2485, in delete_message
    return await self.request(api.Methods.DELETE_MESSAGE, payload)
  File "C:\Users\klim\AppData\Roaming\Python\Python39\site-packages\aiogram\bot\base.py", line 208, in request
    return await api.make_request(self.session, self.server, self.__token, method, data, files,
  File "C:\Users\klim\AppData\Roaming\Python\Python39\site-packages\aiogram\bot\api.py", line 140, in make_request
    return check_result(method, response.content_type, response.status, await response.text())
  File "C:\Users\klim\AppData\Roaming\Python\Python39\site-packages\aiogram\bot\api.py", line 115, in check_result
    exceptions.BadRequest.detect(description)
  File "C:\Users\klim\AppData\Roaming\Python\Python39\site-packages\aiogram\utils\exceptions.py", line 140, in detect
    raise err(cls.text or description)
aiogram.utils.exceptions.MessageToDeleteNotFound: Message to delete not found
ERROR:asyncio:Task exception was never retrieved
future: <Task finished name='Task-128' coro=<Dispatcher._process_polling_updates() done, defined at C:\Users\klim\AppData\Roaming\Python\Python39\site-packages\aiogram\dispatcher\dispatcher.py:401> exception=MessageToDeleteNotFound('Message to delete not found')>
Traceback (most recent call last):
  File "C:\Users\klim\AppData\Roaming\Python\Python39\site-packages\aiogram\dispatcher\dispatcher.py", line 409, in _process_polling_updates
    for responses in itertools.chain.from_iterable(await self.process_updates(updates, fast)):
  File "C:\Users\klim\AppData\Roaming\Python\Python39\site-packages\aiogram\dispatcher\dispatcher.py", line 238, in process_updates
    return await asyncio.gather(*tasks)
  File "C:\Users\klim\AppData\Roaming\Python\Python39\site-packages\aiogram\dispatcher\handler.py", line 116, in notify
    response = await handler_obj.handler(*args, **partial_data)
  File "C:\Users\klim\AppData\Roaming\Python\Python39\site-packages\aiogram\dispatcher\dispatcher.py", line 259, in process_update
    return await self.message_handlers.notify(update.message)
  File "C:\Users\klim\AppData\Roaming\Python\Python39\site-packages\aiogram\dispatcher\handler.py", line 116, in notify
    response = await handler_obj.handler(*args, **partial_data)
  File "C:\Users\klim\Documents\vs code salesfoce\sfExpenceAppBot\secondbot.py", line 337, in echo_message
    await bot.delete_message(msg.chat.id, getBotLatestMessageId())
  File "C:\Users\klim\AppData\Roaming\Python\Python39\site-packages\aiogram\bot\bot.py", line 2485, in delete_message
    return await self.request(api.Methods.DELETE_MESSAGE, payload)
  File "C:\Users\klim\AppData\Roaming\Python\Python39\site-packages\aiogram\bot\base.py", line 208, in request
    return await api.make_request(self.session, self.server, self.__token, method, data, files,
  File "C:\Users\klim\AppData\Roaming\Python\Python39\site-packages\aiogram\bot\api.py", line 140, in make_request
    return check_result(method, response.content_type, response.status, await response.text())
  File "C:\Users\klim\AppData\Roaming\Python\Python39\site-packages\aiogram\bot\api.py", line 115, in check_result
    exceptions.BadRequest.detect(description)
  File "C:\Users\klim\AppData\Roaming\Python\Python39\site-packages\aiogram\utils\exceptions.py", line 140, in detect
    raise err(cls.text or description)
aiogram.utils.exceptions.MessageToDeleteNotFound: Message to delete not found
INFO:root:
        Успешный вход пользователя: Klimchik
        Офис: Office 1
        Email: shpektras@gmail.com
ERROR:asyncio:Task exception was never retrieved
future: <Task finished name='Task-159' coro=<Dispatcher._process_polling_updates() done, defined at C:\Users\klim\AppData\Roaming\Python\Python39\site-packages\aiogram\dispatcher\dispatcher.py:401> exception=MessageToDeleteNotFound('Message to delete not found')>
Traceback (most recent call last):
  File "C:\Users\klim\AppData\Roaming\Python\Python39\site-packages\aiogram\dispatcher\dispatcher.py", line 409, in _process_polling_updates
    for responses in itertools.chain.from_iterable(await self.process_updates(updates, fast)):
  File "C:\Users\klim\AppData\Roaming\Python\Python39\site-packages\aiogram\dispatcher\dispatcher.py", line 238, in process_updates
    return await asyncio.gather(*tasks)
  File "C:\Users\klim\AppData\Roaming\Python\Python39\site-packages\aiogram\dispatcher\handler.py", line 116, in notify
    response = await handler_obj.handler(*args, **partial_data)
  File "C:\Users\klim\AppData\Roaming\Python\Python39\site-packages\aiogram\dispatcher\dispatcher.py", line 259, in process_update
    return await self.message_handlers.notify(update.message)
  File "C:\Users\klim\AppData\Roaming\Python\Python39\site-packages\aiogram\dispatcher\handler.py", line 116, in notify
    response = await handler_obj.handler(*args, **partial_data)
  File "C:\Users\klim\Documents\vs code salesfoce\sfExpenceAppBot\secondbot.py", line 337, in echo_message
    await bot.delete_message(msg.chat.id, msg.message_id)
  File "C:\Users\klim\AppData\Roaming\Python\Python39\site-packages\aiogram\bot\bot.py", line 2485, in delete_message
    return await self.request(api.Methods.DELETE_MESSAGE, payload)
  File "C:\Users\klim\AppData\Roaming\Python\Python39\site-packages\aiogram\bot\base.py", line 208, in request
    return await api.make_request(self.session, self.server, self.__token, method, data, files,
  File "C:\Users\klim\AppData\Roaming\Python\Python39\site-packages\aiogram\bot\api.py", line 140, in make_request
    return check_result(method, response.content_type, response.status, await response.text())
  File "C:\Users\klim\AppData\Roaming\Python\Python39\site-packages\aiogram\bot\api.py", line 115, in check_result
    exceptions.BadRequest.detect(description)
  File "C:\Users\klim\AppData\Roaming\Python\Python39\site-packages\aiogram\utils\exceptions.py", line 140, in detect
    raise err(cls.text or description)
aiogram.utils.exceptions.MessageToDeleteNotFound: Message to delete not found
ERROR:asyncio:Task exception was never retrieved
future: <Task finished name='Task-166' coro=<Dispatcher._process_polling_updates() done, defined at C:\Users\klim\AppData\Roaming\Python\Python39\site-packages\aiogram\dispatcher\dispatcher.py:401> exception=MessageToDeleteNotFound('Message to delete not found')>
Traceback (most recent call last):
  File "C:\Users\klim\AppData\Roaming\Python\Python39\site-packages\aiogram\dispatcher\dispatcher.py", line 409, in _process_polling_updates
    for responses in itertools.chain.from_iterable(await self.process_updates(updates, fast)):
  File "C:\Users\klim\AppData\Roaming\Python\Python39\site-packages\aiogram\dispatcher\dispatcher.py", line 238, in process_updates
    return await asyncio.gather(*tasks)
  File "C:\Users\klim\AppData\Roaming\Python\Python39\site-packages\aiogram\dispatcher\handler.py", line 116, in notify
    response = await handler_obj.handler(*args, **partial_data)
  File "C:\Users\klim\AppData\Roaming\Python\Python39\site-packages\aiogram\dispatcher\dispatcher.py", line 259, in process_update
    return await self.message_handlers.notify(update.message)
  File "C:\Users\klim\AppData\Roaming\Python\Python39\site-packages\aiogram\dispatcher\handler.py", line 116, in notify
    response = await handler_obj.handler(*args, **partial_data)
  File "C:\Users\klim\Documents\vs code salesfoce\sfExpenceAppBot\secondbot.py", line 337, in echo_message
    await bot.delete_message(msg.chat.id, msg.message_id)
  File "C:\Users\klim\AppData\Roaming\Python\Python39\site-packages\aiogram\bot\bot.py", line 2485, in delete_message
    return await self.request(api.Methods.DELETE_MESSAGE, payload)
  File "C:\Users\klim\AppData\Roaming\Python\Python39\site-packages\aiogram\bot\base.py", line 208, in request
    return await api.make_request(self.session, self.server, self.__token, method, data, files,
  File "C:\Users\klim\AppData\Roaming\Python\Python39\site-packages\aiogram\bot\api.py", line 140, in make_request
    return check_result(method, response.content_type, response.status, await response.text())
  File "C:\Users\klim\AppData\Roaming\Python\Python39\site-packages\aiogram\bot\api.py", line 115, in check_result
    exceptions.BadRequest.detect(description)
  File "C:\Users\klim\AppData\Roaming\Python\Python39\site-packages\aiogram\utils\exceptions.py", line 140, in detect
    raise err(cls.text or description)
aiogram.utils.exceptions.MessageToDeleteNotFound: Message to delete not found
